<?xml version="1.0" ?>
<robot name="ufactory_linear_motor" xmlns:xacro="http://www.ros.org/wiki/xacro">

<xacro:include filename="$(find ufactory_linear_motor_description)/urdf/materials.xacro" />
<xacro:include filename="$(find ufactory_linear_motor_description)/urdf/ufactory_linear_motor.trans" />
<xacro:include filename="$(find ufactory_linear_motor_description)/urdf/ufactory_linear_motor.gazebo" />
<link name="base_link">
  <inertial>
    <origin xyz="-0.01124442410905712 -0.053611892391058985 0.027504113501011136" rpy="0 0 0"/>
    <mass value="38.167165545855056"/>
    <inertia ixx="4.03214" iyy="0.12523" izz="4.112446" ixy="-0.033101" iyz="0.032219" ixz="0.004374"/>
  </inertial>
  <visual>
    <origin xyz="0 0 0" rpy="0 0 0"/>
    <geometry>
      <mesh filename="package://ufactory_linear_motor_description/meshes/base_link.stl" scale="0.001 0.001 0.001"/>
    </geometry>
    <material name="silver"/>
  </visual>
  <collision>
    <origin xyz="0 0 0" rpy="0 0 0"/>
    <geometry>
      <mesh filename="package://ufactory_linear_motor_description/meshes/base_link.stl" scale="0.001 0.001 0.001"/>
    </geometry>
  </collision>
</link>

<link name="robot_base_1">
  <inertial>
    <origin xyz="0.04223730861365587 0.08003082547931334 0.01607905560708714" rpy="0 0 0"/>
    <mass value="8.788079551534963"/>
    <inertia ixx="0.023497" iyy="0.022264" izz="0.03835" ixy="0.000234" iyz="0.000477" ixz="0.000414"/>
  </inertial>
  <visual>
    <origin xyz="0.043 0.42 -0.048" rpy="0 0 0"/>
    <geometry>
      <mesh filename="package://ufactory_linear_motor_description/meshes/robot_base_1.stl" scale="0.001 0.001 0.001"/>
    </geometry>
    <material name="silver"/>
  </visual>
  <collision>
    <origin xyz="0.043 0.42 -0.048" rpy="0 0 0"/>
    <geometry>
      <mesh filename="package://ufactory_linear_motor_description/meshes/robot_base_1.stl" scale="0.001 0.001 0.001"/>
    </geometry>
  </collision>
</link>

<joint name="slider_joint" type="prismatic">
  <origin xyz="-0.043 -0.42 0.048" rpy="0 0 0"/>
  <parent link="base_link"/>
  <child link="robot_base_1"/>
  <axis xyz="0.0 -1.0 0.0"/>
  <limit upper="0.0" lower="-0.7" effort="100" velocity="100"/>
</joint>

</robot>
